2020-09-14 16:12:34,676 ERROR: Exception on /favicon.ico [GET] [in /Users/scotthalasy/microblog/venv/lib/python3.7/site-packages/flask/app.py:1892]
Traceback (most recent call last):
  File "/Users/scotthalasy/microblog/venv/lib/python3.7/site-packages/flask/app.py", line 1950, in full_dispatch_request
    rv = self.dispatch_request()
  File "/Users/scotthalasy/microblog/venv/lib/python3.7/site-packages/flask/app.py", line 1926, in dispatch_request
    self.raise_routing_exception(req)
  File "/Users/scotthalasy/microblog/venv/lib/python3.7/site-packages/flask/app.py", line 1908, in raise_routing_exception
    raise request.routing_exception
  File "/Users/scotthalasy/microblog/venv/lib/python3.7/site-packages/flask/ctx.py", line 350, in match_request
    result = self.url_adapter.match(return_rule=True)
  File "/Users/scotthalasy/microblog/venv/lib/python3.7/site-packages/werkzeug/routing.py", line 1945, in match
    raise NotFound()
werkzeug.exceptions.NotFound: 404 Not Found: The requested URL was not found on the server. If you entered the URL manually please check your spelling and try again.

During handling of the above exception, another exception occurred:

Traceback (most recent call last):
  File "/Users/scotthalasy/microblog/venv/lib/python3.7/site-packages/flask/app.py", line 2447, in wsgi_app
    response = self.full_dispatch_request()
  File "/Users/scotthalasy/microblog/venv/lib/python3.7/site-packages/flask/app.py", line 1952, in full_dispatch_request
    rv = self.handle_user_exception(e)
  File "/Users/scotthalasy/microblog/venv/lib/python3.7/site-packages/flask/app.py", line 1816, in handle_user_exception
    return self.handle_http_exception(e)
  File "/Users/scotthalasy/microblog/venv/lib/python3.7/site-packages/flask/app.py", line 1744, in handle_http_exception
    return handler(e)
  File "/Users/scotthalasy/microblog/app/errors.py", line 6, in not_found_error
    return render_template('404.html'), 404
  File "/Users/scotthalasy/microblog/venv/lib/python3.7/site-packages/flask/templating.py", line 140, in render_template
    ctx.app,
  File "/Users/scotthalasy/microblog/venv/lib/python3.7/site-packages/flask/templating.py", line 120, in _render
    rv = template.render(context)
  File "/Users/scotthalasy/microblog/venv/lib/python3.7/site-packages/jinja2/environment.py", line 1090, in render
    self.environment.handle_exception()
  File "/Users/scotthalasy/microblog/venv/lib/python3.7/site-packages/jinja2/environment.py", line 832, in handle_exception
    reraise(*rewrite_traceback_stack(source=source))
  File "/Users/scotthalasy/microblog/venv/lib/python3.7/site-packages/jinja2/_compat.py", line 28, in reraise
    raise value.with_traceback(tb)
  File "/Users/scotthalasy/microblog/app/templates/404.html", line 1, in top-level template code
    {% extends "base.html" %}
  File "/Users/scotthalasy/microblog/venv/lib/python3.7/site-packages/jinja2/environment.py", line 832, in handle_exception
    reraise(*rewrite_traceback_stack(source=source))
  File "/Users/scotthalasy/microblog/venv/lib/python3.7/site-packages/jinja2/_compat.py", line 28, in reraise
    raise value.with_traceback(tb)
  File "/Users/scotthalasy/microblog/app/templates/base.html", line 15, in template
    <a href="{{ url_for('explore', username=current_user.username }}">Explore</a>
jinja2.exceptions.TemplateSyntaxError: unexpected '}', expected ')'
2020-09-14 16:12:35,612 ERROR: Exception on /login [GET] [in /Users/scotthalasy/microblog/venv/lib/python3.7/site-packages/flask/app.py:1892]
Traceback (most recent call last):
  File "/Users/scotthalasy/microblog/venv/lib/python3.7/site-packages/flask/app.py", line 2447, in wsgi_app
    response = self.full_dispatch_request()
  File "/Users/scotthalasy/microblog/venv/lib/python3.7/site-packages/flask/app.py", line 1952, in full_dispatch_request
    rv = self.handle_user_exception(e)
  File "/Users/scotthalasy/microblog/venv/lib/python3.7/site-packages/flask/app.py", line 1821, in handle_user_exception
    reraise(exc_type, exc_value, tb)
  File "/Users/scotthalasy/microblog/venv/lib/python3.7/site-packages/flask/_compat.py", line 39, in reraise
    raise value
  File "/Users/scotthalasy/microblog/venv/lib/python3.7/site-packages/flask/app.py", line 1950, in full_dispatch_request
    rv = self.dispatch_request()
  File "/Users/scotthalasy/microblog/venv/lib/python3.7/site-packages/flask/app.py", line 1936, in dispatch_request
    return self.view_functions[rule.endpoint](**req.view_args)
  File "/Users/scotthalasy/microblog/app/routes.py", line 44, in login
    return render_template('login.html', title='Sign In', form=form)
  File "/Users/scotthalasy/microblog/venv/lib/python3.7/site-packages/flask/templating.py", line 140, in render_template
    ctx.app,
  File "/Users/scotthalasy/microblog/venv/lib/python3.7/site-packages/flask/templating.py", line 120, in _render
    rv = template.render(context)
  File "/Users/scotthalasy/microblog/venv/lib/python3.7/site-packages/jinja2/environment.py", line 1090, in render
    self.environment.handle_exception()
  File "/Users/scotthalasy/microblog/venv/lib/python3.7/site-packages/jinja2/environment.py", line 832, in handle_exception
    reraise(*rewrite_traceback_stack(source=source))
  File "/Users/scotthalasy/microblog/venv/lib/python3.7/site-packages/jinja2/_compat.py", line 28, in reraise
    raise value.with_traceback(tb)
  File "/Users/scotthalasy/microblog/app/templates/login.html", line 1, in top-level template code
    {% extends "base.html" %}
  File "/Users/scotthalasy/microblog/venv/lib/python3.7/site-packages/jinja2/environment.py", line 832, in handle_exception
    reraise(*rewrite_traceback_stack(source=source))
  File "/Users/scotthalasy/microblog/venv/lib/python3.7/site-packages/jinja2/_compat.py", line 28, in reraise
    raise value.with_traceback(tb)
  File "/Users/scotthalasy/microblog/app/templates/base.html", line 15, in template
    <a href="{{ url_for('explore', username=current_user.username }}">Explore</a>
jinja2.exceptions.TemplateSyntaxError: unexpected '}', expected ')'
2020-09-14 16:13:17,120 INFO: BLog startup [in /Users/scotthalasy/microblog/app/__init__.py:41]
2020-09-14 16:13:27,769 ERROR: Exception on /index [GET] [in /Users/scotthalasy/microblog/venv/lib/python3.7/site-packages/flask/app.py:1892]
Traceback (most recent call last):
  File "/Users/scotthalasy/microblog/venv/lib/python3.7/site-packages/flask/app.py", line 2447, in wsgi_app
    response = self.full_dispatch_request()
  File "/Users/scotthalasy/microblog/venv/lib/python3.7/site-packages/flask/app.py", line 1952, in full_dispatch_request
    rv = self.handle_user_exception(e)
  File "/Users/scotthalasy/microblog/venv/lib/python3.7/site-packages/flask/app.py", line 1821, in handle_user_exception
    reraise(exc_type, exc_value, tb)
  File "/Users/scotthalasy/microblog/venv/lib/python3.7/site-packages/flask/_compat.py", line 39, in reraise
    raise value
  File "/Users/scotthalasy/microblog/venv/lib/python3.7/site-packages/flask/app.py", line 1950, in full_dispatch_request
    rv = self.dispatch_request()
  File "/Users/scotthalasy/microblog/venv/lib/python3.7/site-packages/flask/app.py", line 1936, in dispatch_request
    return self.view_functions[rule.endpoint](**req.view_args)
  File "/Users/scotthalasy/microblog/venv/lib/python3.7/site-packages/flask_login/utils.py", line 272, in decorated_view
    return func(*args, **kwargs)
  File "/Users/scotthalasy/microblog/app/routes.py", line 90, in index
    posts = current_user.followed_posts.all()
AttributeError: 'function' object has no attribute 'all'
2020-09-14 16:14:56,145 INFO: BLog startup [in /Users/scotthalasy/microblog/app/__init__.py:41]
2020-09-14 16:14:59,817 ERROR: Exception on /index [GET] [in /Users/scotthalasy/microblog/venv/lib/python3.7/site-packages/flask/app.py:1892]
Traceback (most recent call last):
  File "/Users/scotthalasy/microblog/venv/lib/python3.7/site-packages/flask/app.py", line 2447, in wsgi_app
    response = self.full_dispatch_request()
  File "/Users/scotthalasy/microblog/venv/lib/python3.7/site-packages/flask/app.py", line 1952, in full_dispatch_request
    rv = self.handle_user_exception(e)
  File "/Users/scotthalasy/microblog/venv/lib/python3.7/site-packages/flask/app.py", line 1821, in handle_user_exception
    reraise(exc_type, exc_value, tb)
  File "/Users/scotthalasy/microblog/venv/lib/python3.7/site-packages/flask/_compat.py", line 39, in reraise
    raise value
  File "/Users/scotthalasy/microblog/venv/lib/python3.7/site-packages/flask/app.py", line 1950, in full_dispatch_request
    rv = self.dispatch_request()
  File "/Users/scotthalasy/microblog/venv/lib/python3.7/site-packages/flask/app.py", line 1936, in dispatch_request
    return self.view_functions[rule.endpoint](**req.view_args)
  File "/Users/scotthalasy/microblog/venv/lib/python3.7/site-packages/flask_login/utils.py", line 272, in decorated_view
    return func(*args, **kwargs)
  File "/Users/scotthalasy/microblog/app/routes.py", line 89, in index
    posts = current_user.followed_posts().all()
  File "/Users/scotthalasy/microblog/app/models.py", line 61, in followed_posts
    own = Post.query.filter(user_id == self.id)
NameError: name 'user_id' is not defined
